2019-01-22 14:48:43,057 ERROR: Exception on / [GET] [in /Users/quinnangill/Desktop/flask_tutorial/microblog/venv/lib/python3.7/site-packages/flask/app.py:1761]
Traceback (most recent call last):
  File "/Users/quinnangill/Desktop/flask_tutorial/microblog/venv/lib/python3.7/site-packages/flask/app.py", line 2292, in wsgi_app
    response = self.full_dispatch_request()
  File "/Users/quinnangill/Desktop/flask_tutorial/microblog/venv/lib/python3.7/site-packages/flask/app.py", line 1815, in full_dispatch_request
    rv = self.handle_user_exception(e)
  File "/Users/quinnangill/Desktop/flask_tutorial/microblog/venv/lib/python3.7/site-packages/flask/app.py", line 1718, in handle_user_exception
    reraise(exc_type, exc_value, tb)
  File "/Users/quinnangill/Desktop/flask_tutorial/microblog/venv/lib/python3.7/site-packages/flask/_compat.py", line 35, in reraise
    raise value
  File "/Users/quinnangill/Desktop/flask_tutorial/microblog/venv/lib/python3.7/site-packages/flask/app.py", line 1813, in full_dispatch_request
    rv = self.dispatch_request()
  File "/Users/quinnangill/Desktop/flask_tutorial/microblog/venv/lib/python3.7/site-packages/flask/app.py", line 1799, in dispatch_request
    return self.view_functions[rule.endpoint](**req.view_args)
  File "/Users/quinnangill/Desktop/flask_tutorial/microblog/venv/lib/python3.7/site-packages/flask_login/utils.py", line 260, in decorated_view
    return current_app.login_manager.unauthorized()
  File "/Users/quinnangill/Desktop/flask_tutorial/microblog/venv/lib/python3.7/site-packages/flask_login/login_manager.py", line 175, in unauthorized
    redirect_url = make_login_url(login_view, next_url=request.url)
  File "/Users/quinnangill/Desktop/flask_tutorial/microblog/venv/lib/python3.7/site-packages/flask_login/utils.py", line 112, in login_url
    base = expand_login_view(login_view)
  File "/Users/quinnangill/Desktop/flask_tutorial/microblog/venv/lib/python3.7/site-packages/flask_login/utils.py", line 89, in expand_login_view
    return url_for(login_view)
  File "/Users/quinnangill/Desktop/flask_tutorial/microblog/venv/lib/python3.7/site-packages/flask/helpers.py", line 356, in url_for
    return appctx.app.handle_url_build_error(error, endpoint, values)
  File "/Users/quinnangill/Desktop/flask_tutorial/microblog/venv/lib/python3.7/site-packages/flask/app.py", line 2061, in handle_url_build_error
    reraise(exc_type, exc_value, tb)
  File "/Users/quinnangill/Desktop/flask_tutorial/microblog/venv/lib/python3.7/site-packages/flask/_compat.py", line 35, in reraise
    raise value
  File "/Users/quinnangill/Desktop/flask_tutorial/microblog/venv/lib/python3.7/site-packages/flask/helpers.py", line 345, in url_for
    force_external=external)
  File "/Users/quinnangill/Desktop/flask_tutorial/microblog/venv/lib/python3.7/site-packages/werkzeug/routing.py", line 1776, in build
    raise BuildError(endpoint, values, method, self)
werkzeug.routing.BuildError: Could not build url for endpoint 'login'. Did you mean 'auth.login' instead?
2019-01-22 14:49:19,963 ERROR: Exception on /index [GET] [in /Users/quinnangill/Desktop/flask_tutorial/microblog/venv/lib/python3.7/site-packages/flask/app.py:1761]
Traceback (most recent call last):
  File "/Users/quinnangill/Desktop/flask_tutorial/microblog/venv/lib/python3.7/site-packages/flask/app.py", line 2292, in wsgi_app
    response = self.full_dispatch_request()
  File "/Users/quinnangill/Desktop/flask_tutorial/microblog/venv/lib/python3.7/site-packages/flask/app.py", line 1815, in full_dispatch_request
    rv = self.handle_user_exception(e)
  File "/Users/quinnangill/Desktop/flask_tutorial/microblog/venv/lib/python3.7/site-packages/flask/app.py", line 1718, in handle_user_exception
    reraise(exc_type, exc_value, tb)
  File "/Users/quinnangill/Desktop/flask_tutorial/microblog/venv/lib/python3.7/site-packages/flask/_compat.py", line 35, in reraise
    raise value
  File "/Users/quinnangill/Desktop/flask_tutorial/microblog/venv/lib/python3.7/site-packages/flask/app.py", line 1813, in full_dispatch_request
    rv = self.dispatch_request()
  File "/Users/quinnangill/Desktop/flask_tutorial/microblog/venv/lib/python3.7/site-packages/flask/app.py", line 1799, in dispatch_request
    return self.view_functions[rule.endpoint](**req.view_args)
  File "/Users/quinnangill/Desktop/flask_tutorial/microblog/venv/lib/python3.7/site-packages/flask_login/utils.py", line 260, in decorated_view
    return current_app.login_manager.unauthorized()
  File "/Users/quinnangill/Desktop/flask_tutorial/microblog/venv/lib/python3.7/site-packages/flask_login/login_manager.py", line 175, in unauthorized
    redirect_url = make_login_url(login_view, next_url=request.url)
  File "/Users/quinnangill/Desktop/flask_tutorial/microblog/venv/lib/python3.7/site-packages/flask_login/utils.py", line 112, in login_url
    base = expand_login_view(login_view)
  File "/Users/quinnangill/Desktop/flask_tutorial/microblog/venv/lib/python3.7/site-packages/flask_login/utils.py", line 89, in expand_login_view
    return url_for(login_view)
  File "/Users/quinnangill/Desktop/flask_tutorial/microblog/venv/lib/python3.7/site-packages/flask/helpers.py", line 356, in url_for
    return appctx.app.handle_url_build_error(error, endpoint, values)
  File "/Users/quinnangill/Desktop/flask_tutorial/microblog/venv/lib/python3.7/site-packages/flask/app.py", line 2061, in handle_url_build_error
    reraise(exc_type, exc_value, tb)
  File "/Users/quinnangill/Desktop/flask_tutorial/microblog/venv/lib/python3.7/site-packages/flask/_compat.py", line 35, in reraise
    raise value
  File "/Users/quinnangill/Desktop/flask_tutorial/microblog/venv/lib/python3.7/site-packages/flask/helpers.py", line 345, in url_for
    force_external=external)
  File "/Users/quinnangill/Desktop/flask_tutorial/microblog/venv/lib/python3.7/site-packages/werkzeug/routing.py", line 1776, in build
    raise BuildError(endpoint, values, method, self)
werkzeug.routing.BuildError: Could not build url for endpoint 'login'. Did you mean 'auth.login' instead?
2019-01-22 14:49:20,680 ERROR: Exception on /explore [GET] [in /Users/quinnangill/Desktop/flask_tutorial/microblog/venv/lib/python3.7/site-packages/flask/app.py:1761]
Traceback (most recent call last):
  File "/Users/quinnangill/Desktop/flask_tutorial/microblog/venv/lib/python3.7/site-packages/flask/app.py", line 2292, in wsgi_app
    response = self.full_dispatch_request()
  File "/Users/quinnangill/Desktop/flask_tutorial/microblog/venv/lib/python3.7/site-packages/flask/app.py", line 1815, in full_dispatch_request
    rv = self.handle_user_exception(e)
  File "/Users/quinnangill/Desktop/flask_tutorial/microblog/venv/lib/python3.7/site-packages/flask/app.py", line 1718, in handle_user_exception
    reraise(exc_type, exc_value, tb)
  File "/Users/quinnangill/Desktop/flask_tutorial/microblog/venv/lib/python3.7/site-packages/flask/_compat.py", line 35, in reraise
    raise value
  File "/Users/quinnangill/Desktop/flask_tutorial/microblog/venv/lib/python3.7/site-packages/flask/app.py", line 1813, in full_dispatch_request
    rv = self.dispatch_request()
  File "/Users/quinnangill/Desktop/flask_tutorial/microblog/venv/lib/python3.7/site-packages/flask/app.py", line 1799, in dispatch_request
    return self.view_functions[rule.endpoint](**req.view_args)
  File "/Users/quinnangill/Desktop/flask_tutorial/microblog/venv/lib/python3.7/site-packages/flask_login/utils.py", line 260, in decorated_view
    return current_app.login_manager.unauthorized()
  File "/Users/quinnangill/Desktop/flask_tutorial/microblog/venv/lib/python3.7/site-packages/flask_login/login_manager.py", line 175, in unauthorized
    redirect_url = make_login_url(login_view, next_url=request.url)
  File "/Users/quinnangill/Desktop/flask_tutorial/microblog/venv/lib/python3.7/site-packages/flask_login/utils.py", line 112, in login_url
    base = expand_login_view(login_view)
  File "/Users/quinnangill/Desktop/flask_tutorial/microblog/venv/lib/python3.7/site-packages/flask_login/utils.py", line 89, in expand_login_view
    return url_for(login_view)
  File "/Users/quinnangill/Desktop/flask_tutorial/microblog/venv/lib/python3.7/site-packages/flask/helpers.py", line 356, in url_for
    return appctx.app.handle_url_build_error(error, endpoint, values)
  File "/Users/quinnangill/Desktop/flask_tutorial/microblog/venv/lib/python3.7/site-packages/flask/app.py", line 2061, in handle_url_build_error
    reraise(exc_type, exc_value, tb)
  File "/Users/quinnangill/Desktop/flask_tutorial/microblog/venv/lib/python3.7/site-packages/flask/_compat.py", line 35, in reraise
    raise value
  File "/Users/quinnangill/Desktop/flask_tutorial/microblog/venv/lib/python3.7/site-packages/flask/helpers.py", line 345, in url_for
    force_external=external)
  File "/Users/quinnangill/Desktop/flask_tutorial/microblog/venv/lib/python3.7/site-packages/werkzeug/routing.py", line 1776, in build
    raise BuildError(endpoint, values, method, self)
werkzeug.routing.BuildError: Could not build url for endpoint 'login'. Did you mean 'auth.login' instead?
